Workbook

Sheet Leggimi
A1: Backlog FitSlot: proposta da discutere
A3: Cos'è | B3: Una proposta di temi, epic, user story, task tecnici e spike ricavata dal vostro «Resoconto Completo». Non è una versione definitiva: serve per discutere, tagliare e riordinare.
A4: Contenuto | B4: 6 temi, 22 epic, 85 storie, 5 task tecnici, 5 spike (95 voci in tutto). Le prime 7 colonne del foglio «Backlog proposto» sono nello stesso ordine del template Excel (Ordine, ID, Titolo, Descrizione, Valore di business, Story Point, Nello sprint?).
A5: Come copiare nel template | B5: Selezionate le righe che volete tenere (colonne A-G) e incollatele nel template con «Incolla speciale > Valori», così non portate con voi colori e formati. Le colonne I-N (tema, epic, tipo, dipendenze, sprint suggerito, note) servono solo per la discussione.
A6: Cosa compilare voi | B6: Story Point (colonna F) e Nello sprint? (colonna G), celle in giallo: sono volutamente vuote. Gli story point si stimano con il planning poker; nessuna stima qui dentro.
A7: Valore di business | B7: Proposta mia, da rivedere. Menu a tendina Basso / Medio / Alto con colori (verde, arancione, rosso).
A8: Ordine e sprint suggerito | B8: L'ordine tiene conto del valore e delle dipendenze (controllate: nessuna voce viene prima di ciò da cui dipende). Gli sprint S2-S4 sono volutamente pieni: servono per scegliere cosa tagliare in base alla vostra capacità.
A9: Criteri di accettazione | B9: Sono già scritti per le voci dei primi sprint (formato Dato che / quando / allora) e stanno nella colonna Descrizione, sotto la storia. Per le altre voci vanno scritti prima di entrare in uno sprint.
A10: Da discutere | B10: Il foglio «Da discutere» raccoglie 18 decisioni da prendere e verifiche da fare con il professore. Alcune voci rimandano ai codici D1, D2, ecc.
A11: Regole di dominio | B11: Le note indicano quando una regola viene da una risposta del professore e quando dalle note di altri gruppi (da confermare).

Sheet Backlog proposto
A1: Ordine | B1: ID | C1: Titolo | D1: Descrizione | E1: Valore di business | F1: Story Point | G1: Nello sprint? (x) | I1: Tema | J1: Epic | K1: Tipo | L1: Dipendenze | M1: Sprint suggerito | N1: Note e punti da discutere
A2: 1 | B2: TK-01 | C2: Creare il progetto Maven con architettura a livelli | D2: Task: creare il progetto con Maven e organizzarlo a livelli (interfaccia, servizi, repository), così che le regole stiano fuori dall'interfaccia e si possano testare. | E2: Medio | I2: Tema 6 · Fondamenta tecniche | J2: E6.1 Task tecnici | K2: Task tecnico | M2: S1 | N2: Da fare insieme alle prime storie, non da solo.
A3: 2 | B3: TK-02 | C3: Schema del database e script SQL | D3: Task: definire lo schema del database (utenti e ruoli, iscritti, certificati, abbonamenti, strutture, corsi, lezioni, prenotazioni, ingressi) e scrivere gli script SQL di creazione e di dati di prova. | E3: Medio | I3: Tema 6 · Fondamenta tecniche | J3: E6.1 Task tecnici | K3: Task tecnico | M3: S1 | N3: Tenere distinti corso (ricorrente) e lezione (singola data).
A4: 3 | B4: TK-03 | C4: Database di test e prima suite di test | D4: Task: preparare un database di test e scrivere i primi test (JUnit), così da seguire il TDD fin dal primo sprint. | E4: Medio | I4: Tema 6 · Fondamenta tecniche | J4: E6.1 Task tecnici | K4: Task tecnico | L4: TK-01, TK-02 | M4: S1
A5: 4 | B5: UE-01 | C5: Registrare un nuovo iscritto | D5: Come reception, voglio registrare un nuovo iscritto con i suoi dati anagrafici e di contatto, così da averlo in anagrafica e poterlo gestire. Criteri di accettazione: 1) Dato che sono la reception, quando inserisco nome, cognome, data di nascita e un recapito e confermo, allora l'iscritto compare in anagrafica con un codice univoco. 2) Dato che manca un dato obbligatorio, quando provo a confermare, allora vedo quale dato manca e l'iscritto non viene creato. 3) Dato che esiste già un iscritto con gli stessi dati identificativi, quando provo a registrarlo, allora vedo un avviso di possibile duplicato. | E5: Alto | I5: Tema 1 · Anagrafica, accesso e conformità sanitaria | J5: E1.1 Registrazione e anagrafica iscritti | K5: Storia | M5: S1 | N5: Candidata a storia di riferimento (2 punti) per il planning poker: piccola e chiara.
A6: 5 | B6: UE-04 | C6: Cercare un iscritto | D6: Come reception, voglio cercare un iscritto per nome, cognome o codice, così da trovarlo subito mentre è al banco. Criteri di accettazione: 1) Dato che esistono più iscritti con lo stesso cognome, quando cerco per cognome, allora vedo l'elenco di tutti quelli corrispondenti con nome e codice. 2) Dato che nessun iscritto corrisponde, quando cerco, allora vedo un messaggio di «nessun risultato». | E6: Alto | I6: Tema 1 · Anagrafica, accesso e conformità sanitaria | J6: E1.1 Registrazione e anagrafica iscritti | K6: Storia | L6: UE-01 | M6: S1
A7: 6 | B7: UE-05 | C7: Accedere con le mie credenziali | D7: Come utente registrato, voglio accedere con le mie credenziali personali, così da usare il sistema in modo sicuro e riconoscibile. Criteri di accettazione: 1) Dato che ho credenziali valide, quando le inserisco, allora accedo alle funzioni che mi spettano. 2) Dato che le credenziali sono sbagliate, quando provo ad accedere, allora vedo un messaggio di errore e non entro. 3) Dato che ho effettuato l'accesso, quando esco, allora per rientrare devo inserire di nuovo le credenziali. | E7: Alto | I7: Tema 1 · Anagrafica, accesso e conformità sanitaria | J7: E1.2 Accesso e ruoli | K7: Storia | L7: UE-01 | M7: S1
A8: 7 | B8: UE-06 | C8: Vedere solo le funzioni del mio ruolo | D8: Come gestore, voglio che ogni utente veda e usi solo le funzioni del proprio ruolo, così da evitare operazioni non autorizzate. Criteri di accettazione: 1) Dato che sono un iscritto, quando accedo, allora non vedo le funzioni riservate a reception, istruttori e gestore. 2) Dato che sono la reception, quando accedo, allora posso registrare iscritti e ingressi ma non modificare il listino. | E8: Alto | I8: Tema 1 · Anagrafica, accesso e conformità sanitaria | J8: E1.2 Accesso e ruoli | K8: Storia | L8: UE-05 | M8: S1
A9: 8 | B9: UE-08 | C9: Registrare un certificato cartaceo | D9: Come reception, voglio registrare un certificato medico consegnato su carta, dopo averlo controllato, con la sua data di scadenza, così da aggiornare subito la posizione dell'iscritto. Criteri di accettazione: 1) Dato che un iscritto consegna il certificato, quando inserisco la data di scadenza e confermo, allora il certificato risulta valido fino a quella data. 2) Dato che la data di scadenza è già passata, quando provo a registrarlo, allora vedo un avviso e il certificato non risulta valido. | E9: Alto | I9: Tema 1 · Anagrafica, accesso e conformità sanitaria | J9: E1.3 Certificato medico | K9: Storia | L9: UE-01 | M9: S1 | N9: Il controllo del cartaceo è visivo e va fatto una sola volta (risposta del professore).
A10: 9 | B10: UE-15 | C10: Definire un tipo di abbonamento | D10: Come gestore, voglio definire un tipo di abbonamento (durata o numero di ingressi, servizi inclusi, fasce orarie, prezzo), così da offrire formule diverse ai clienti. Criteri di accettazione: 1) Dato che sono il gestore, quando definisco un abbonamento a 10 ingressi valido per sala pesi e corsi con un prezzo e confermo, allora il tipo compare nel listino con le sue caratteristiche. 2) Dato che manca il prezzo o la durata o il numero di ingressi, quando confermo, allora vedo cosa manca e il tipo non viene creato. | E10: Alto | I10: Tema 2 · Abbonamenti, crediti e pagamenti | J10: E2.1 Tipi di abbonamento | K10: Storia | L10: UE-06 | M10: S1 | N10: La traccia parla di un abbonamento a 10 ingressi: vedi D6 sul listino.
A11: 10 | B11: UE-18 | C11: Assegnare un abbonamento in reception | D11: Come reception, voglio assegnare un abbonamento a un iscritto, così da attivarlo subito al momento della vendita. Criteri di accettazione: 1) Dato che l'iscritto non ha un abbonamento attivo, quando gli assegno un tipo di abbonamento a tempo, allora l'abbonamento risulta attivo con data di inizio e di scadenza. 2) Dato che assegno un abbonamento a ingressi, quando confermo, allora gli ingressi residui sono pari a quelli del tipo scelto. | E11: Alto | I11: Tema 2 · Abbonamenti, crediti e pagamenti | J11: E2.2 Assegnazione e consultazione abbonamenti | K11: Storia | L11: UE-01, UE-15 | M11: S1 | N11: In questo sprint la vendita non registra ancora il pagamento (UE-27).
A12: 11 | B12: UE-60 | C12: Registrare un ingresso con esito | D12: Come reception, voglio registrare l'ingresso di un iscritto e vedere subito se può entrare e per quale attività, così da non far entrare chi non è in regola. Criteri di accettazione: 1) Dato che l'iscritto ha certificato e abbonamento validi, quando registro l'ingresso, allora vedo «ammesso» e l'ingresso viene registrato con data e ora. 2) Dato che il certificato è scaduto, quando registro l'ingresso, allora vedo «non ammesso» con il motivo e l'ingresso non viene registrato. 3) Dato che l'abbonamento è scaduto, quando registro l'ingresso, allora vedo «non ammesso» con il motivo. | E12: Alto | I12: Tema 4 · Operatività giornaliera | J12: E4.1 Controllo accessi | K12: Storia | L12: UE-04, UE-08, UE-18 | M12: S1 | N12: Affronta il problema principale della reception («ogni lunedì entrano venti persone con il certificato scaduto»). Nello sprint 1 non controlla ancora capienza né prenotazione (UE-62, UE-63).
A13: 12 | B13: UE-61 | C13: Vedere il motivo del rifiuto | D13: Come reception, voglio vedere il motivo preciso del rifiuto (certificato scaduto, abbonamento scaduto, servizio non incluso, fuori fascia oraria, ingressi esauriti), così da spiegarlo all'iscritto. Criteri di accettazione: 1) Dato che l'abbonamento non include la piscina, quando registro un ingresso in piscina, allora vedo «servizio non incluso». 2) Dato che l'abbonamento vale solo di mattina, quando registro un ingresso alle 17:00, allora vedo «fuori fascia oraria». 3) Dato che ho 0 ingressi residui, quando registro un ingresso, allora vedo «ingressi esauriti». | E13: Medio | I13: Tema 4 · Operatività giornaliera | J13: E4.1 Controllo accessi | K13: Storia | L13: UE-60 | M13: S1 | N13: Se risulta troppo piccola si può unire a UE-60.
A14: 13 | B14: SP-01 | C14: Spike: tempi limite e scadenze | D14: Spike: capire come gestire eventi che scattano nel tempo (offerte di subentro che scadono, avvisi sul certificato, lezioni da annullare) e produrre un piccolo prototipo. | E14: Alto | I14: Tema 6 · Fondamenta tecniche | J14: E6.2 Spike (indagini) | K14: Spike | M14: S2 | N14: Output: scelta motivata e prototipo. Limite di tempo da fissare (ad esempio un giorno di lavoro).
A15: 14 | B15: SP-02 | C15: Spike: due persone prenotano l'ultimo posto | D15: Spike: capire come evitare che due prenotazioni simultanee superino la capienza. | E15: Alto | I15: Tema 6 · Fondamenta tecniche | J15: E6.2 Spike (indagini) | K15: Spike | L15: TK-02 | M15: S2
A16: 15 | B16: TK-04 | C16: Orario controllabile nei test | D16: Task: far arrivare l'orario corrente al codice dall'esterno, così da testare le regole sulle 2 ore e sulle scadenze senza aspettare. | E16: Medio | I16: Tema 6 · Fondamenta tecniche | J16: E6.1 Task tecnici | K16: Task tecnico | L16: TK-01 | M16: S2
A17: 16 | B17: UE-07 | C17: Assegnare più ruoli a una persona | D17: Come gestore, voglio assegnare più ruoli alla stessa persona (ad esempio istruttore e iscritto), così da rappresentare chi insegna e allo stesso tempo frequenta il centro. Criteri di accettazione: 1) Dato che una persona è sia istruttore sia iscritta, quando accede, allora può scegliere con quale ruolo operare. 2) Dato che opera come istruttore, quando consulta le funzioni, allora vede solo quelle da istruttore. | E17: Medio | I17: Tema 1 · Anagrafica, accesso e conformità sanitaria | J17: E1.2 Accesso e ruoli | K17: Storia | L17: UE-06 | M17: S2 | N17: Esempio fatto dal professore.
A18: 17 | B18: UE-34 | C18: Definire strutture e capienze | D18: Come gestore, voglio definire sale corsi, sala pesi e piscina con la capienza massima e gli orari prenotabili, così da non superare i posti disponibili. Criteri di accettazione: 1) Dato che sono il gestore, quando creo la sala yoga con 20 posti e confermo, allora la struttura compare con capienza 20. 2) Dato che inserisco una capienza non positiva, quando confermo, allora vedo un errore e la struttura non viene creata. | E18: Alto | I18: Tema 3 · Palinsesto, prenotazioni e liste d'attesa | J18: E3.1 Palinsesto e strutture | K18: Storia | L18: UE-06 | M18: S2 | N18: Risposta del professore: tutto è a capienza (corsi, sala pesi, piscina).
A19: 18 | B19: UE-35 | C19: Creare un corso fisso | D19: Come gestore, voglio creare un corso ricorrente (sala, giorno, ora, posti massimi), così da pubblicare il palinsesto. Criteri di accettazione: 1) Dato che creo yoga il martedì alle 18:30 in sala 1 con 20 posti, quando confermo, allora il corso compare ogni martedì. 2) Dato che la sala è già occupata in quell'orario, quando provo a creare un secondo corso, allora vedo un avviso e il corso non viene creato. | E19: Alto | I19: Tema 3 · Palinsesto, prenotazioni e liste d'attesa | J19: E3.1 Palinsesto e strutture | K19: Storia | L19: UE-34 | M19: S2 | N19: Distinguere il corso (ricorrente) dalla lezione (singola data): prenotazioni e annullamenti riguardano la lezione.
A20: 19 | B20: UE-36 | C20: Vedere il palinsesto con i posti liberi | D20: Come iscritto, voglio vedere il palinsesto con i posti ancora liberi per ogni lezione, così da scegliere cosa prenotare. Criteri di accettazione: 1) Dato che una lezione ha 20 posti e 17 prenotati, quando guardo il palinsesto, allora vedo «3 posti liberi». 2) Dato che la lezione è piena, quando guardo il palinsesto, allora vedo «completo». | E20: Alto | I20: Tema 3 · Palinsesto, prenotazioni e liste d'attesa | J20: E3.1 Palinsesto e strutture | K20: Storia | L20: UE-35, UE-05 | M20: S2
A21: 20 | B21: UE-39 | C21: Prenotare un posto in un corso | D21: Come iscritto, voglio prenotare un posto in una lezione con posti liberi, così da essere sicuro di averlo. Criteri di accettazione: 1) Dato che la lezione ha posti liberi, quando prenoto, allora la prenotazione è confermata e i posti liberi diminuiscono di uno. 2) Dato che la lezione è piena, quando provo a prenotare, allora vedo che è completa e la prenotazione non viene creata. 3) Dato che ho già una prenotazione per quella lezione, quando provo a prenotare di nuovo, allora vedo un avviso. | E21: Alto | I21: Tema 3 · Palinsesto, prenotazioni e liste d'attesa | J21: E3.2 Prenotazioni | K21: Storia | L21: UE-36, SP-02 | M21: S2 | N21: Attenzione al caso di due persone che prenotano l'ultimo posto (SP-02).
A22: 21 | B22: UE-42 | C22: Cancellare una prenotazione | D22: Come iscritto, voglio cancellare una mia prenotazione, così da liberare il posto se non posso andare. Criteri di accettazione: 1) Dato che ho una prenotazione futura, quando la cancello, allora sparisce dalle mie prenotazioni e il posto torna libero. 2) Dato che la lezione è già iniziata, quando provo a cancellare, allora vedo che non è più possibile. | E22: Alto | I22: Tema 3 · Palinsesto, prenotazioni e liste d'attesa | J22: E3.2 Prenotazioni | K22: Storia | L22: UE-39 | M22: S2
A23: 22 | B23: UE-43 | C23: Vedere le mie prenotazioni | D23: Come iscritto, voglio vedere le mie prenotazioni future e il loro stato (confermata, in lista d'attesa), così da organizzarmi. | E23: Medio | I23: Tema 3 · Palinsesto, prenotazioni e liste d'attesa | J23: E3.2 Prenotazioni | K23: Storia | L23: UE-39 | M23: S2
A24: 23 | B24: UE-11 | C24: Vedere lo stato del mio certificato | D24: Come iscritto, voglio vedere se il mio certificato è valido, in attesa di verifica o scaduto e fino a quando vale, così da sapere se posso prenotare ed entrare. Criteri di accettazione: 1) Dato che il mio certificato è valido, quando apro il mio profilo, allora vedo «valido» e la data di scadenza. 2) Dato che il mio certificato è scaduto, quando apro il mio profilo, allora vedo «scaduto» e l'indicazione di portarne uno nuovo. | E24: Medio | I24: Tema 1 · Anagrafica, accesso e conformità sanitaria | J24: E1.3 Certificato medico | K24: Storia | L24: UE-05, UE-08 | M24: S2
A25: 24 | B25: UE-12 | C25: Bloccare le prenotazioni senza certificato valido | D25: Come gestore, voglio che chi ha il certificato scaduto o non ancora verificato non possa prenotare, così da evitare accessi non regolari al centro. Criteri di accettazione: 1) Dato che il mio certificato è scaduto, quando provo a prenotare, allora la prenotazione è rifiutata con il motivo «certificato scaduto». 2) Dato che il mio certificato scade domani, quando prenoto una lezione di oggi, allora la prenotazione è accettata. 3) Dato che il mio certificato non è ancora stato verificato, quando provo a prenotare, allora la prenotazione è rifiutata con il motivo «certificato in attesa di verifica». | E25: Alto | I25: Tema 1 · Anagrafica, accesso e conformità sanitaria | J25: E1.3 Certificato medico | K25: Storia | L25: UE-08, UE-39 | M25: S2 | N25: Regola presa dalle note di altri gruppi: da confermare (D14). Vedi anche D13.
A26: 25 | B26: UE-19 | C26: Vedere il mio abbonamento | D26: Come iscritto, voglio vedere tipo, scadenza e ingressi residui del mio abbonamento, così da sapere cosa posso fare. Criteri di accettazione: 1) Dato che ho un abbonamento a 10 ingressi con 4 usati, quando apro il mio profilo, allora vedo «6 ingressi residui» e la data di scadenza. 2) Dato che il mio abbonamento è scaduto, quando apro il mio profilo, allora vedo «scaduto». | E26: Medio | I26: Tema 2 · Abbonamenti, crediti e pagamenti | J26: E2.2 Assegnazione e consultazione abbonamenti | K26: Storia | L26: UE-05, UE-18 | M26: S2
A27: 26 | B27: UE-21 | C27: Un ingresso per ogni attività | D27: Come iscritto con abbonamento a ingressi, voglio che ogni attività (un corso, un accesso in sala pesi o in piscina) consumi un solo ingresso, così da sapere esattamente quanti me ne restano. Criteri di accettazione: 1) Dato che ho 5 ingressi, quando partecipo a un corso e poi entro in piscina nello stesso giorno, allora me ne restano 3. 2) Dato che ho un abbonamento a tempo, quando partecipo a un'attività, allora non vengono scalati ingressi. | E27: Alto | I27: Tema 2 · Abbonamenti, crediti e pagamenti | J27: E2.3 Crediti (ingressi) | K27: Storia | L27: UE-18, UE-60 | M27: S2 | N27: Risposta del professore: un ingresso vale per una singola attività.
A28: 27 | B28: UE-22 | C28: Riservare l'ingresso alla prenotazione | D28: Come iscritto con abbonamento a ingressi, voglio che l'ingresso venga riservato quando la prenotazione è confermata, così da non prenotare più attività di quelle che posso pagare. Criteri di accettazione: 1) Dato che ho 1 ingresso, quando prenoto un corso, allora l'ingresso risulta riservato e non posso prenotare un'altra attività. 2) Dato che ho riservato l'ingresso, quando partecipo e l'ingresso viene registrato, allora l'ingresso riservato risulta usato. | E28: Alto | I28: Tema 2 · Abbonamenti, crediti e pagamenti | J28: E2.3 Crediti (ingressi) | K28: Storia | L28: UE-21, UE-39 | M28: S2 | N28: Regola proposta da noi (D1): il professore ha detto «dipende dalla lista e dal tempo limite per cancellarsi».
A29: 28 | B29: UE-23 | C29: Riavere l'ingresso se cancello in tempo | D29: Come iscritto, voglio riavere l'ingresso se cancello almeno 2 ore prima dell'inizio, così da non perderlo se cambio programma. Criteri di accettazione: 1) Dato che ho una prenotazione che inizia tra 3 ore, quando la cancello, allora l'ingresso torna disponibile. 2) Dato che mancano esattamente 2 ore all'inizio, quando cancello, allora l'ingresso torna disponibile. | E29: Medio | I29: Tema 2 · Abbonamenti, crediti e pagamenti | J29: E2.3 Crediti (ingressi) | K29: Storia | L29: UE-22, UE-42 | M29: S2
A30: 29 | B30: SP-03 | C30: Spike: file del certificato | D30: Spike: capire dove e come conservare il file del certificato e chi può vederlo. | E30: Medio | I30: Tema 6 · Fondamenta tecniche | J30: E6.2 Spike (indagini) | K30: Spike | M30: S3
A31: 30 | B31: SP-04 | C31: Spike: invio degli avvisi | D31: Spike: decidere come inviare gli avvisi (nel sistema ed e-mail simulata) e come collegarli alle regole. | E31: Medio | I31: Tema 6 · Fondamenta tecniche | J31: E6.2 Spike (indagini) | K31: Spike | M31: S3
A32: 31 | B32: TK-05 | C32: Integrazione continua | D32: Task: configurare l'esecuzione automatica dei test a ogni push su GitHub. | E32: Basso | I32: Tema 6 · Fondamenta tecniche | J32: E6.1 Task tecnici | K32: Task tecnico | L32: TK-03 | M32: S3 | N32: Opzionale: verificare che sia gradita.
A33: 32 | B33: UE-77 | C33: Vedere le mie notifiche | D33: Come utente registrato, voglio vedere le mie notifiche nel sistema, così da non perdermi avvisi importanti. Criteri di accettazione: 1) Dato che ho una nuova notifica, quando apro l'elenco, allora la vedo in cima con data e testo. 2) Dato che non ho notifiche, quando apro l'elenco, allora vedo un messaggio che dice che non ce ne sono. | E33: Alto | I33: Tema 4 · Operatività giornaliera | J33: E4.5 Notifiche | K33: Storia | L33: UE-05, SP-04 | M33: S3 | N33: Il modo di avvisare è a nostra discrezione (risposta del professore).
A34: 33 | B34: UE-09 | C34: Caricare il file del certificato | D34: Come iscritto, voglio caricare il file del mio certificato medico dal sistema, così da non dover portare il cartaceo in reception. | E34: Medio | I34: Tema 1 · Anagrafica, accesso e conformità sanitaria | J34: E1.3 Certificato medico | K34: Storia | L34: UE-05, SP-03 | M34: S3 | N34: Il certificato resta «in attesa di verifica» finché la reception non lo valida (UE-10).
A35: 34 | B35: UE-10 | C35: Validare un certificato caricato | D35: Come reception, voglio verificare il certificato caricato da un iscritto e confermarne validità e scadenza, una volta sola, così da sbloccarlo per prenotazioni e ingressi. | E35: Medio | I35: Tema 1 · Anagrafica, accesso e conformità sanitaria | J35: E1.3 Certificato medico | K35: Storia | L35: UE-09 | M35: S3
A36: 35 | B36: UE-14 | C36: Proteggere i dati del certificato | D36: Come iscritto, voglio che il mio certificato medico sia visibile solo a me e al personale autorizzato, così da proteggere i miei dati sanitari. Criteri di accettazione: 1) Dato che sono un altro iscritto, quando cerco di vedere il certificato di una persona diversa da me, allora non è accessibile. 2) Dato che sono la reception, quando consulto la scheda di un iscritto, allora vedo lo stato e la scadenza del suo certificato. | E36: Medio | I36: Tema 1 · Anagrafica, accesso e conformità sanitaria | J36: E1.3 Certificato medico | K36: Storia | L36: UE-06, UE-08 | M36: S3 | N36: Il certificato è un dato sanitario.
A37: 36 | B37: UE-26 | C37: Bloccare le prenotazioni senza ingressi | D37: Come gestore, voglio che chi ha finito gli ingressi non possa prenotare, così da evitare prestazioni non pagate. Criteri di accettazione: 1) Dato che non ho ingressi disponibili, quando provo a prenotare, allora la prenotazione è rifiutata con il motivo «ingressi esauriti». | E37: Medio | I37: Tema 2 · Abbonamenti, crediti e pagamenti | J37: E2.3 Crediti (ingressi) | K37: Storia | L37: UE-22 | M37: S3
A38: 37 | B38: UE-40 | C38: Prenotare sala pesi o piscina | D38: Come iscritto, voglio prenotare un posto in sala pesi o in piscina nella fascia che mi serve, così da non trovare il centro pieno. | E38: Medio | I38: Tema 3 · Palinsesto, prenotazioni e liste d'attesa | J38: E3.2 Prenotazioni | K38: Storia | L38: UE-34, UE-39 | M38: S3
A39: 38 | B39: UE-44 | C39: Evitare prenotazioni sovrapposte | D39: Come iscritto, voglio non poter prenotare due attività nello stesso orario, così da non impegnarmi in due posti insieme. Criteri di accettazione: 1) Dato che sono prenotato a un corso alle 18:30, quando provo a prenotare un altro corso alle 18:30, allora la prenotazione è rifiutata con il motivo «sovrapposizione». | E39: Medio | I39: Tema 3 · Palinsesto, prenotazioni e liste d'attesa | J39: E3.2 Prenotazioni | K39: Storia | L39: UE-39 | M39: S3 | N39: La lista d'attesa su più corsi nello stesso orario è invece ammessa (UE-51).
A40: 39 | B40: UE-45 | C40: Mettermi in lista d'attesa | D40: Come iscritto, voglio entrare in lista d'attesa quando la lezione è piena, così da avere una possibilità se si libera un posto. Criteri di accettazione: 1) Dato che la lezione è piena, quando scelgo la lista d'attesa, allora risulto in coda con la mia posizione. 2) Dato che sono già in coda per quella lezione, quando provo a rimettermi, allora vedo un avviso. | E40: Alto | I40: Tema 3 · Palinsesto, prenotazioni e liste d'attesa | J40: E3.3 Liste d'attesa e subentri | K40: Storia | L40: UE-39 | M40: S3
...

Sheet Epic e temi
A1: Tema | B1: Epic | C1: Cosa copre | D1: N. voci | E1: di cui valore Alto | F1: Perché in questo ordine
A2: Tema 1 · Anagrafica, accesso e conformità sanitaria | B2: E1.1 Registrazione e anagrafica iscritti | C2: Creare, correggere e cercare gli iscritti. | D2: =COUNTIF('Backlog proposto'!$J$2:$J$96,B2) -> 4 | E2: =COUNTIFS('Backlog proposto'!$J$2:$J$96,B2,'Backlog proposto'!$E$2:$E$96,"Alto") -> 2 | F2: Senza iscritti in anagrafica non si può fare nulla. La prima storia è piccola e chiara: candidata a storia di riferimento per le stime.
A3: Tema 1 · Anagrafica, accesso e conformità sanitaria | B3: E1.2 Accesso e ruoli | C3: Login, funzioni per ruolo, persone con più ruoli. | D3: =COUNTIF('Backlog proposto'!$J$2:$J$96,B3) -> 3 | E3: =COUNTIFS('Backlog proposto'!$J$2:$J$96,B3,'Backlog proposto'!$E$2:$E$96,"Alto") -> 2 | F3: Il professore ha chiarito che iscritti, istruttori e reception usano lo stesso sistema: i permessi vanno costruiti prima delle funzioni sensibili.
A4: Tema 1 · Anagrafica, accesso e conformità sanitaria | B4: E1.3 Certificato medico | C4: Registrazione, caricamento, validazione, stato, blocco delle prenotazioni, avvisi, privacy. | D4: =COUNTIF('Backlog proposto'!$J$2:$J$96,B4) -> 7 | E4: =COUNTIFS('Backlog proposto'!$J$2:$J$96,B4,'Backlog proposto'!$E$2:$E$96,"Alto") -> 2 | F4: È il problema più sentito dalla reception (certificati scaduti agli ingressi): il certificato cartaceo entra subito, il resto segue.
A5: Tema 2 · Abbonamenti, crediti e pagamenti | B5: E2.1 Tipi di abbonamento | C5: Listino: tipi, servizi inclusi, fasce orarie, prezzi. | D5: =COUNTIF('Backlog proposto'!$J$2:$J$96,B5) -> 3 | E5: =COUNTIFS('Backlog proposto'!$J$2:$J$96,B5,'Backlog proposto'!$E$2:$E$96,"Alto") -> 1 | F5: Serve il listino per vendere abbonamenti e per sapere cosa un iscritto può fare.
A6: Tema 2 · Abbonamenti, crediti e pagamenti | B6: E2.2 Assegnazione e consultazione abbonamenti | C6: Vendita in reception, vista dell'iscritto, rinnovo. | D6: =COUNTIF('Backlog proposto'!$J$2:$J$96,B6) -> 3 | E6: =COUNTIFS('Backlog proposto'!$J$2:$J$96,B6,'Backlog proposto'!$E$2:$E$96,"Alto") -> 1 | F6: Collega iscritti e listino: abilita il controllo degli ingressi già nel primo sprint.
A7: Tema 2 · Abbonamenti, crediti e pagamenti | B7: E2.3 Crediti (ingressi) | C7: Riserva, consumo, restituzione e perdita degli ingressi. | D7: =COUNTIF('Backlog proposto'!$J$2:$J$96,B7) -> 6 | E7: =COUNTIFS('Backlog proposto'!$J$2:$J$96,B7,'Backlog proposto'!$E$2:$E$96,"Alto") -> 2 | F7: Dipende dalle prenotazioni: viene dopo il palinsesto. Le regole su restituzione e perdita sono dettate dal professore.
A8: Tema 2 · Abbonamenti, crediti e pagamenti | B8: E2.4 Pagamenti e ricevute | C8: Registrare i pagamenti, emettere ricevute, pagare dal sistema. | D8: =COUNTIF('Backlog proposto'!$J$2:$J$96,B8) -> 3 | E8: =COUNTIFS('Backlog proposto'!$J$2:$J$96,B8,'Backlog proposto'!$E$2:$E$96,"Alto") -> 0 | F8: Obbligatori per gli incassi, ma non bloccano le funzioni principali: arrivano dopo il nucleo di prenotazioni.
A9: Tema 2 · Abbonamenti, crediti e pagamenti | B9: E2.5 Congelamento per infortunio | C9: Congelare, limite di 30 giorni l'anno, scadenza, prenotazioni. | D9: =COUNTIF('Backlog proposto'!$J$2:$J$96,B9) -> 4 | E9: =COUNTIFS('Backlog proposto'!$J$2:$J$96,B9,'Backlog proposto'!$E$2:$E$96,"Alto") -> 0 | F9: Regola importante ma poco frequente, con molti punti ancora aperti: dopo il nucleo.
A10: Tema 3 · Palinsesto, prenotazioni e liste d'attesa | B10: E3.1 Palinsesto e strutture | C10: Strutture con capienza, corsi fissi, lezioni, soglia minima. | D10: =COUNTIF('Backlog proposto'!$J$2:$J$96,B10) -> 5 | E10: =COUNTIFS('Backlog proposto'!$J$2:$J$96,B10,'Backlog proposto'!$E$2:$E$96,"Alto") -> 3 | F10: Senza strutture e corsi non c'è nulla da prenotare.
A11: Tema 3 · Palinsesto, prenotazioni e liste d'attesa | B11: E3.2 Prenotazioni | C11: Prenotare, cancellare, vedere le proprie prenotazioni, evitare sovrapposizioni. | D11: =COUNTIF('Backlog proposto'!$J$2:$J$96,B11) -> 6 | E11: =COUNTIFS('Backlog proposto'!$J$2:$J$96,B11,'Backlog proposto'!$E$2:$E$96,"Alto") -> 2 | F11: Risolve il problema delle liti sui posti: è il valore più alto per gli iscritti.
A12: Tema 3 · Palinsesto, prenotazioni e liste d'attesa | B12: E3.3 Liste d'attesa e subentri | C12: Coda, offerta di subentro con tempo limite, idoneità, più liste nello stesso orario. | D12: =COUNTIF('Backlog proposto'!$J$2:$J$96,B12) -> 9 | E12: =COUNTIFS('Backlog proposto'!$J$2:$J$96,B12,'Backlog proposto'!$E$2:$E$96,"Alto") -> 5 | F12: È la parte con più regole e casi limite (caso di Marco): serve dopo prenotazioni e notifiche.
A13: Tema 3 · Palinsesto, prenotazioni e liste d'attesa | B13: E3.4 Priorità e penalità | C13: Penalità per cancellazioni tardive e assenze, blocco temporaneo, bonus di priorità. | D13: =COUNTIF('Backlog proposto'!$J$2:$J$96,B13) -> 6 | E13: =COUNTIFS('Backlog proposto'!$J$2:$J$96,B13,'Backlog proposto'!$E$2:$E$96,"Alto") -> 0 | F13: Scoraggia assenze e cancellazioni tardive; dipende da prenotazioni, ingressi e liste d'attesa.
... A23: Tema 6 · Fondamenta tecniche | B23: E6.2 Spike (indagini) | C23: Indagini brevi su tempi limite, concorrenza, file e avvisi. | D23: =COUNTIF('Backlog proposto'!$J$2:$J$96,B23) -> 5 | E23: =COUNTIFS('Backlog proposto'!$J$2:$J$96,B23,'Backlog proposto'!$E$2:$E$96,"Alto") -> 2 | F23: Riducono l'incertezza prima di stimare e costruire le storie che ne dipendono.
C24: Totale | D24: =SUM(D2:D23) -> 95 | E24: =SUM(E2:E23) -> 28

Sheet Da discutere
A1: Codice | B1: Argomento | C1: Domanda o proposta | D1: Voci coinvolte | E1: Da chiedere al professore? | F1: Decisione del gruppo
A2: D1 | B2: Crediti | C2: Quando si riserva, si consuma e si restituisce un ingresso? Proposta: riserva alla prenotazione confermata (o subentro accettato); consumo all'ingresso registrato; perdita se cancello a meno di 2 ore o non mi presento; restituzione se cancello in tempo o se la lezione è annullata. | D2: UE-21, UE-22, UE-23, UE-24, UE-25 | E2: No (scelta nostra)
A3: D2 | B3: Subentri | C3: La tabella con 4 finestre di tempo (3 ore, 1 ora, 30 minuti, 15 minuti) più un secondo avviso è molto complessa. Proposta: partire con un solo tempo limite configurabile e aggiungere finestre solo se serve. | D3: UE-47, UE-48, UE-59, SP-01 | E3: No (scelta nostra)
A4: D3 | B4: Penalità | C4: Il blocco dura 5 giorni oppure vale per «il turno successivo»? Va scelta un'unica regola (proposta: 5 giorni, per lo stesso tipo di corso) e chiarito se vale per tutte le attività. | D4: UE-54, UE-55, UE-56 | E4: No (scelta nostra)
A5: D4 | B5: Subentri | C5: Se l'iscritto non risponde all'offerta, subisce penalità? Il professore ha detto solo che rifiutare in tempo non ne comporta. Proposta: il silenzio vale come rifiuto tardivo. | D5: UE-48, UE-49 | E5: Conviene chiedere
A6: D5 | B6: Priorità | C6: Il bonus di priorità per chi non riesce mai a subentrare compare nelle note di altri gruppi con la frase tagliata. Il professore l'ha detto davvero? | D6: UE-58 | E6: Sì
A7: D6 | B7: Listino | C7: La traccia parla di un abbonamento a 10 ingressi, mentre la vostra tabella prezzi ha pacchetti da 8 e da 12. Aggiungere il pacchetto da 10 (prezzo coerente, ad esempio intorno ai 100 euro) per restare fedeli alla traccia. | D7: UE-15, UE-16 | E7: No (scelta nostra)
A8: D7 | B8: Studenti | C8: «Mattina» significa che l'attività inizia entro le 13:30? Come si verifica lo stato di studente? | D8: UE-17 | E8: No (scelta nostra)
A9: D8 | B9: Ingressi | C9: In sala pesi e in piscina si può entrare senza prenotazione se c'è posto, o la prenotazione è sempre obbligatoria? | D9: UE-40, UE-63 | E9: Sì
A10: D9 | B10: Ingressi | C10: La reception può forzare un ingresso con certificato scaduto? Il professore non ha risposto. Coerente con il blocco totale: non consentito. | D10: UE-60 | E10: Conviene chiedere
A11: D10 | B11: Congelamento | C11: La scadenza dell'abbonamento slitta dei giorni congelati? Le prenotazioni nel periodo si annullano? Non chiarito. Proposta: sì a entrambe. | D11: UE-30, UE-32, UE-33 | E11: Conviene chiedere
A12: D11 | B12: Registrazione | C12: L'iscritto crea da solo il proprio account oppure lo crea sempre la reception? | D12: UE-02 | E12: Sì
A13: D12 | B13: Uscite | C13: Se la reception dimentica di registrare un'uscita, si chiude automaticamente a fine giornata? Proposta: sì, all'orario di chiusura. | D13: UE-64, UE-65 | E13: No (scelta nostra)
... A19: D18 | B19: Storico corsi | C19: Il 70% di annullamenti si calcola sugli ultimi 30 giorni o sulle ultime 10 lezioni? Il vostro documento riporta entrambe le alternative: sceglierne una. | D19: UE-84 | E19: No (scelta nostra)
